<?xml version="1.0" ?>
<!-- =================================================================================== -->
<!-- |    This document was autogenerated by xacro from create.urdf.xacro              | -->
<!-- |    EDITING THIS FILE BY HAND IS NOT RECOMMENDED                                 | -->
<!-- =================================================================================== -->
<robot name="create" xmlns:controller="http://playerstage.sourceforge.net/gazebo/xmlschema/#controller" xmlns:interface="http://playerstage.sourceforge.net/gazebo/xmlschema/#interface" xmlns:sensor="http://playerstage.sourceforge.net/gazebo/xmlschema/#sensor">
  <!-- Included URDF Files -->
  <material name="Black">
    <color rgba="0.0 0.0 0.0 1.0"/>
  </material>
  <material name="Blue">
    <color rgba="0.0 0.0 0.8 1.0"/>
  </material>
  <material name="Green">
    <color rgba="0.0 0.8 0.0 1.0"/>
  </material>
  <material name="Grey">
    <color rgba="0.7 0.7 0.7 1.0"/>
  </material>
  <material name="Grey2">
    <color rgba="0.9 0.9 0.9 1.0"/>
  </material>
  <material name="Red">
    <color rgba="0.8 0.0 0.0 1.0"/>
  </material>
  <material name="White">
    <color rgba="1.0 1.0 1.0 1.0"/>
  </material>
  <link name="base_footprint">
    <inertial>
      <mass value="0.0001"/>
      <origin xyz="0 0 0"/>
      <inertia ixx="0.0001" ixy="0.0" ixz="0.0" iyy="0.0001" iyz="0.0" izz="0.0001"/>
    </inertial>
    <visual>
      <origin rpy="0 0 0" xyz="0 0 0"/>
      <geometry>
        <box size="0.001 0.001 0.001"/>
      </geometry>
      <material name="Green"/>
    </visual>
    <collision>
      <origin rpy="0 0 0" xyz="0 0 0.1285"/>
      <geometry>
        <box size="0.001 0.001 0.001"/>
      </geometry>
    </collision>
  </link>
  <joint name="base_footprint_joint" type="fixed">
    <!-- NB: While you would think this would make it go up, it is oddly reversed.
                 This moves the joint to 0,0,0 where we want it for rviz, etc. -->
    <origin rpy="0 0 0" xyz="0 0 0.1285"/>
    <parent link="base_footprint"/>
    <child link="base_link"/>
  </joint>
  <link name="base_link">
    <inertial>
      <mass value="12"/>
      <origin xyz="-0.1085 0 -0.0775"/>
      <inertia ixx="1.0" ixy="0.0" ixz="0.0" iyy="1.0" iyz="0.0" izz="1.0"/>
    </inertial>
    <visual>
      <origin rpy="0 0 0" xyz="0.0 0.0 0.0"/>
      <geometry>
        <mesh filename="package://irobot_create_description/meshes/create_body.dae"/>
      </geometry>
      <material name="Blue"/>
    </visual>
    <collision>
      <origin rpy="0 0 0" xyz="0.0 0.0 0.0"/>
      <geometry>
        <mesh filename="package://irobot_create_description/meshes/create_body.stl"/>
      </geometry>
    </collision>
  </link>
  <joint name="rear_wheel_joint" type="continuous">
    <origin rpy="0 0 0" xyz="-0.12 0 -0.035"/>
    <parent link="base_link"/>
    <child link="rear_wheel_link"/>
    <axis xyz="0 1 0"/>
    <anchor xyz="0 0 0"/>
    <limit effort="10" k_velocity="0" velocity="100"/>
    <joint_properties damping="0.0" friction="0.0"/>
  </joint>
  <link name="rear_wheel_link">
    <inertial>
      <mass value="0.001"/>
      <origin xyz="0 0 0"/>
      <inertia ixx="0.012411765597" ixy="-0.000711733678" ixz="0.00050272983" iyy="0.015218160428" iyz="-0.000004273467" izz="0.011763977943"/>
    </inertial>
    <visual>
      <origin rpy="1.570795 0 0" xyz="0 0 0"/>
      <geometry>
        <sphere radius="0.008"/>
      </geometry>
      <material name="Blue"/>
    </visual>
    <collision>
      <origin rpy="1.570795 0 0" xyz="0 0 0"/>
      <geometry>
        <sphere radius="0.008"/>
      </geometry>
    </collision>
  </link>
  <gazebo reference="rear_wheel_link">
    <elem key="mu1" value="10.0"/>
    <elem key="mu2" value="10.0"/>
    <elem key="kp" value="1000000.0"/>
    <elem key="kd" value="1.0"/>
  </gazebo>
  <joint name="base_caster_support_joint" type="continuous">
    <origin rpy="0 0 0" xyz="0.13 0 -0.023"/>
    <parent link="base_link"/>
    <child link="base_caster_support_link"/>
    <axis xyz="0 0 1"/>
    <anchor xyz="0.01 0 0"/>
    <limit effort="100" k_velocity="0" velocity="100"/>
    <joint_properties damping="0.0" friction="0.0"/>
  </joint>
  <transmission name="rear_wheel_trans" type="pr2_mechanism_model/SimpleTransmission">
    <actuator name="rear_wheel_motor"/>
    <joint name="rear_wheel_joint"/>
    <mechanicalReduction>1.0</mechanicalReduction>
  </transmission>
  <link name="base_caster_support_link">
    <inertial>
      <mass value="25.0"/>
      <origin xyz="0 0 0"/>
      <inertia ixx="0.01" ixy="0.0" ixz="0.0" iyy="0.01" iyz="0.0" izz="0.01"/>
    </inertial>
    <visual>
      <origin rpy="0 0 0" xyz="0.0 0.0 0.0"/>
      <geometry>
        <cylinder length="0.037" radius="0.001"/>
      </geometry>
    </visual>
    <collision>
      <origin rpy="0 0 0" xyz="0.0 0.0 0.0"/>
      <geometry>
        <cylinder length="0.037" radius="0.001"/>
      </geometry>
    </collision>
  </link>
  <joint name="caster_wheel_joint" type="continuous">
    <origin rpy="0 0 0" xyz="-0.008 0 -0.0130"/>
    <parent link="base_caster_support_link"/>
    <child link="caster_wheel_link"/>
    <axis xyz="0 1 0"/>
    <anchor xyz="0 0 0"/>
    <limit effort="100" k_velocity="0" velocity="100"/>
    <joint_properties damping="0.0" friction="0.0"/>
  </joint>
  <transmission name="caster_wheel_trans" type="pr2_mechanism_model/SimpleTransmission">
    <actuator name="caster_wheel_motor"/>
    <joint name="caster_wheel_joint"/>
    <mechanicalReduction>1.0</mechanicalReduction>
  </transmission>
  <link name="caster_wheel_link">
    <inertial>
      <mass value="1.0"/>
      <origin rpy="0 0 0" xyz="0 0 0"/>
      <inertia ixx="0.012411765597" ixy="-0.000711733678" ixz="0.00050272983" iyy="0.015218160428" iyz="-0.000004273467" izz="0.011763977943"/>
    </inertial>
    <visual>
      <origin rpy="1.570795 0 0" xyz="0 0 0"/>
      <geometry>
        <cylinder length="0.015" radius="0.007"/>
      </geometry>
    </visual>
    <collision>
      <origin rpy="1.570795 0 0" xyz="0 0 0"/>
      <geometry>
        <cylinder length="0.015" radius="0.007"/>
      </geometry>
    </collision>
  </link>
  <gazebo reference="caster_wheel_link">
    <elem key="mu1" value="50.0"/>
    <elem key="mu2" value="50.0"/>
    <elem key="kp" value="1000000.0"/>
    <elem key="kd" value="1.0"/>
  </gazebo>
  <joint name="base_link_left_motor_joint" type="fixed">
    <origin rpy="0 0 0" xyz="0 0.105 -0.0128"/>
    <parent link="base_link"/>
    <child link="base_link_left_motor_link"/>
  </joint>
  <link name="base_link_left_motor_link">
    <inertial>
      <mass value="0.1"/>
      <origin xyz=" 0 0.009375 0 "/>
      <inertia ixx="0.012411765597" ixy="0.0" ixz="0.0" iyy="0.015218160428" iyz="0.0" izz="0.011763977943"/>
    </inertial>
    <visual>
      <origin rpy="1.570795 0 0" xyz="0 0.009375 0"/>
      <geometry>
        <cylinder length="0.025" radius="0.009"/>
      </geometry>
    </visual>
    <collision>
      <origin rpy="1.570795 0 0" xyz="0 0.009375 0"/>
      <geometry>
        <cylinder length="0.025" radius="0.009"/>
      </geometry>
    </collision>
  </link>
  <joint name="base_link_left_wheel_joint" type="continuous">
    <origin rpy="0 0 0" xyz="0 0.01875 0"/>
    <axis xyz="0 1 0"/>
    <anchor xyz="0 0 0"/>
    <limit effort="100" velocity="100"/>
    <joint_properties damping="0.0" friction="0.0"/>
    <parent link="base_link_left_motor_link"/>
    <child link="base_link_left_wheel_link"/>
  </joint>
  <link name="base_link_left_wheel_link">
    <inertial>
      <mass value="5"/>
      <origin xyz=" 0 0 0 "/>
      <inertia ixx="0.012411765597" ixy="0.0" ixz="0.0" iyy="0.015218160428" iyz="0.0" izz="0.011763977943"/>
    </inertial>
    <visual>
      <origin rpy="1.570795 0 0" xyz="0 0.009375 0"/>
      <geometry>
        <cylinder length="0.03" radius="0.032"/>
      </geometry>
      <material name="Black"/>
    </visual>
    <collision>
      <origin rpy="1.570795 0 0" xyz="0 0.009375 0"/>
      <geometry>
        <cylinder length="0.03" radius="0.032"/>
      </geometry>
    </collision>
  </link>
  <gazebo reference="base_link_left_wheel_link">
    <elem key="mu1" value="50.0"/>
    <elem key="mu2" value="50.0"/>
    <elem key="kp" value="100000000.0"/>
    <elem key="kd" value="1.0"/>
    <material>Create/Grey</material>
  </gazebo>
  <gazebo reference="base_link_left_motor_link">
    <material>Create/White</material>
  </gazebo>
  <transmission name="base_link_left_wheel_trans" type="pr2_mechanism_model/SimpleTransmission">
    <actuator name="base_link_left_wheel_motor"/>
    <joint name="base_link_left_wheel_joint"/>
    <mechanicalReduction>1.0</mechanicalReduction>
  </transmission>
  <joint name="base_link_right_motor_joint" type="fixed">
    <origin rpy="0 0 0" xyz="0 -0.105 -0.0128"/>
    <parent link="base_link"/>
    <child link="base_link_right_motor_link"/>
  </joint>
  <link name="base_link_right_motor_link">
    <inertial>
      <mass value="0.1"/>
      <origin xyz=" 0 -0.009375 0 "/>
      <inertia ixx="0.012411765597" ixy="0.0" ixz="0.0" iyy="0.015218160428" iyz="0.0" izz="0.011763977943"/>
    </inertial>
    <visual>
      <origin rpy="1.570795 0 0" xyz="0 -0.009375 0"/>
      <geometry>
        <cylinder length="0.025" radius="0.009"/>
      </geometry>
    </visual>
    <collision>
      <origin rpy="1.570795 0 0" xyz="0 -0.009375 0"/>
      <geometry>
        <cylinder length="0.025" radius="0.009"/>
      </geometry>
    </collision>
  </link>
  <joint name="base_link_right_wheel_joint" type="continuous">
    <origin rpy="0 0 0" xyz="0 -0.01875 0"/>
    <axis xyz="0 1 0"/>
    <anchor xyz="0 0 0"/>
    <limit effort="100" velocity="100"/>
    <joint_properties damping="0.0" friction="0.0"/>
    <parent link="base_link_right_motor_link"/>
    <child link="base_link_right_wheel_link"/>
  </joint>
  <link name="base_link_right_wheel_link">
    <inertial>
      <mass value="5"/>
      <origin xyz=" 0 0 0 "/>
      <inertia ixx="0.012411765597" ixy="0.0" ixz="0.0" iyy="0.015218160428" iyz="0.0" izz="0.011763977943"/>
    </inertial>
    <visual>
      <origin rpy="1.570795 0 0" xyz="0 -0.009375 0"/>
      <geometry>
        <cylinder length="0.03" radius="0.032"/>
      </geometry>
      <material name="Black"/>
    </visual>
    <collision>
      <origin rpy="1.570795 0 0" xyz="0 -0.009375 0"/>
      <geometry>
        <cylinder length="0.03" radius="0.032"/>
      </geometry>
    </collision>
  </link>
  <gazebo reference="base_link_right_wheel_link">
    <elem key="mu1" value="50.0"/>
    <elem key="mu2" value="50.0"/>
    <elem key="kp" value="100000000.0"/>
    <elem key="kd" value="1.0"/>
    <material>Create/Grey</material>
  </gazebo>
  <gazebo reference="base_link_right_motor_link">
    <material>Create/White</material>
  </gazebo>
  <transmission name="base_link_right_wheel_trans" type="pr2_mechanism_model/SimpleTransmission">
    <actuator name="base_link_right_wheel_motor"/>
    <joint name="base_link_right_wheel_joint"/>
    <mechanicalReduction>1.0</mechanicalReduction>
  </transmission>
  <gazebo>
    <controller:diffdrive_plugin name="differential_drive_controller" plugin="libdiffdrive_plugin.so">
      <alwaysOn>true</alwaysOn>
      <update>100</update>
      <updateRate>100.0</updateRate>
      <leftJoint>base_link_right_wheel_joint</leftJoint>
      <rightJoint>base_link_left_wheel_joint</rightJoint>
      <wheelSeparation>0.34</wheelSeparation>
      <wheelDiameter>0.0692</wheelDiameter>
      <torque>50</torque>
      <interface:position name="position_iface_0"/>
      <robotNamespace>/</robotNamespace>
      <topicName>cmd_vel</topicName>
    </controller:diffdrive_plugin>
    <controller:gazebo_ros_p3d name="p3d_base_controller" plugin="libgazebo_ros_p3d.so">
      <alwaysOn>true</alwaysOn>
      <updateRate>100.0</updateRate>
      <bodyName>base_link</bodyName>
      <topicName>base_pose_ground_truth</topicName>
      <gaussianNoise>0.01</gaussianNoise>
      <frameName>map</frameName>
      <xyzOffsets>0 0 0</xyzOffsets>
      <rpyOffsets>0 0 0</rpyOffsets>
      <interface:position name="p3d_base_position"/>
    </controller:gazebo_ros_p3d>
    <canonicalBody>base_footprint</canonicalBody>
    <!-- this publishes empty joint_states due to no transmission, but
             triggering robot_state_publisher to publish tf between fixed joints in create,
             (e.g. base_laser_link for the base_scan frame) -->
    <controller:gazebo_ros_controller_manager name="gazebo_ros_controller_manager" plugin="libgazebo_ros_controller_manager.so">
      <alwaysOn>true</alwaysOn>
      <updateRate>100.0</updateRate>
      <interface:audio name="gazebo_ros_controller_manager_dummy_iface"/>
    </controller:gazebo_ros_controller_manager>
  </gazebo>
  <gazebo reference="base_link">
    <material>Create/GreyTextured</material>
  </gazebo>
  <gazebo reference="rear_wheel_link">
    <material>Create/Black</material>
  </gazebo>
  <gazebo reference="caster_wheel_link">
    <material>Create/Black</material>
  </gazebo>
  <gazebo reference="base_caster_box_link">
    <material>Create/Black</material>
  </gazebo>
  <gazebo reference="base_caster_support_link">
    <material>Create/Black</material>
  </gazebo>
</robot>

