<?xml version="1.0" ?>
<sdf version="1.4">
    <model name="elias">
        <pose>0 0 0.1961 0 0 0</pose>
        <static>false</static>
        <link name="chassis">
            <inertial>
                <mass>1.0</mass>
                <inertia>
                    <ixx>1.0</ixx>
                    <ixy>0.0</ixy>
                    <ixz>0.0</ixz>
                    <iyy>1.0</iyy>
                    <iyz>0.0</iyz>
                    <izz>1.0</izz>
                </inertia>
            </inertial>
            <collision name="main_frame">
                <pose>0 0 0 0 0 0</pose>
                <geometry>
                    <box>
                        <size>1.05 0.1 0.1</size>
                    </box>
                </geometry>
            </collision>
            <collision name="front_axle">
                <pose>0.53 0 0 0 0 0</pose>
                <geometry>
                    <box>
                        <size>0.1 0.38 0.1</size>
                    </box>
                </geometry>
            </collision>
            <collision name="rear_axle">
                <pose>-0.53 0 0 0 0 0</pose>
                <geometry>
                    <box>
                        <size>0.1 0.38 0.1</size>
                    </box>
                </geometry>
            </collision>
            <collision name="bucket">
				<pose>0.53 0 0.15 1.57 0 3.14</pose>
                <geometry>
                    <mesh>
                        <uri>model://elias/meshes/bucket.dae</uri>
                    </mesh>
                </geometry>
            </collision>
            <visual name="main_frame">
                <pose>0 0 0 0 0 0</pose>
                <geometry>
                    <box>
                        <size>0.96 0.1 0.1</size>
                    </box>
                </geometry>
                <material>
                    <script>
                        <uri>file://media/materials/scripts/gazebo.material</uri>
                        <name>Gazebo/Red</name>
                    </script>
                </material>
            </visual>
            <visual name="front_axle">
                <pose>0.53 0 0 0 0 0</pose>
                <geometry>
                    <box>
                        <size>0.1 0.38 0.1</size>
                    </box>
                </geometry>
                <material>
                    <script>
                        <uri>file://media/materials/scripts/gazebo.material</uri>
                        <name>Gazebo/Red</name>
                    </script>
                </material>
            </visual>
            <visual name="rear_axle">
                <pose>-0.53 0 0 0 0 0</pose>
                <geometry>
                    <box>
                        <size>0.1 0.38 0.1</size>
                    </box>
                </geometry>
                <material>
                    <script>
                        <uri>file://media/materials/scripts/gazebo.material</uri>
                        <name>Gazebo/Red</name>
                    </script>
                </material>
            </visual>
            <visual name="bucket">
				<pose>0.53 0 0.15 1.57 0 3.14</pose>
                <geometry>
                    <mesh>
                        <uri>model://elias/meshes/bucket.dae</uri>
                    </mesh>
                </geometry>
                <material>
                    <script>
                        <uri>file://media/materials/scripts/gazebo.material</uri>
                        <name>Gazebo/Grey</name>
                    </script>
                </material>
            </visual>
            <velocity_decay>
                <linear>0</linear>
                <angular>0</angular>
            </velocity_decay>
        </link>
        <link name="left_front_wheel">
            <pose>0.53 0.335 -0.0466 0 1.57 1.57</pose>
            <inertial>
                <mass>0.1</mass>
            </inertial>
            <collision name="collision">
                <geometry>
                    <cylinder>
                        <radius>0.1495</radius>
                        <length>0.1</length>
                    </cylinder>
                </geometry>
                <surface>
                    <friction>
                        <ode>
                            <mu>100000.0</mu>
                            <mu2>100000.0</mu2>
                            <slip1>0.0</slip1>
                            <slip2>0.0</slip2>
                        </ode>
                    </friction>
                </surface>
            </collision>
            <visual name="visual">
                <geometry>
                    <mesh>
                        <uri>model://elias/meshes/wheel.dae</uri>
                    </mesh>
                </geometry>
                <material>
                    <script>
                        <uri>file://media/materials/scripts/gazebo.material</uri>
                        <name>Gazebo/Yellow</name>
                    </script>
                </material>
            </visual>
            <velocity_decay>
                <linear>0</linear>
                <angular>0</angular>
            </velocity_decay>
        </link>
        <link name="right_front_wheel">
            <pose>0.53 -0.335 -0.0466 0 1.57 1.57</pose>
            <inertial>
                <mass>0.1</mass>
            </inertial>
            <collision name="collision">
                <geometry>
                    <cylinder>
                        <radius>0.1495</radius>
                        <length>0.1</length>
                    </cylinder>
                </geometry>
                <surface>
                    <friction>
                        <ode>
                            <mu>100000.0</mu>
                            <mu2>100000.0</mu2>
                            <slip1>0.0</slip1>
                            <slip2>0.0</slip2>
                        </ode>
                    </friction>
                </surface>
            </collision>
            <visual name="visual">
                <geometry>
                    <mesh>
                        <uri>model://elias/meshes/wheel.dae</uri>
                    </mesh>
                </geometry>
                <material>
                    <script>
                        <uri>file://media/materials/scripts/gazebo.material</uri>
                        <name>Gazebo/Yellow</name>
                    </script>
                </material>
            </visual>
            <velocity_decay>
                <linear>0</linear>
                <angular>0</angular>
            </velocity_decay>
        </link>
        <link name="left_rear_wheel">
            <pose>-0.53 0.335 -0.0466 0 1.57 1.57</pose>
            <inertial>
                <mass>0.1</mass>
            </inertial>
            <collision name="collision">
                <geometry>
                    <cylinder>
                        <radius>0.1495</radius>
                        <length>0.1</length>
                    </cylinder>
                </geometry>
                <surface>
                    <friction>
                        <ode>
                            <mu>100000.0</mu>
                            <mu2>100000.0</mu2>
                            <slip1>0.0</slip1>
                            <slip2>0.0</slip2>
                        </ode>
                    </friction>
                </surface>
            </collision>
            <visual name="visual">
                <geometry>
                    <mesh>
                        <uri>model://elias/meshes/wheel.dae</uri>
                    </mesh>
                </geometry>
                <material>
                    <script>
                        <uri>file://media/materials/scripts/gazebo.material</uri>
                        <name>Gazebo/Yellow</name>
                    </script>
                </material>
            </visual>
            <velocity_decay>
                <linear>0</linear>
                <angular>0</angular>
            </velocity_decay>
        </link>
        <link name="right_rear_wheel">
            <pose>-0.53 -0.335 -0.0466 0 1.57 1.57</pose>
            <inertial>
                <mass>0.1</mass>
            </inertial>
            <collision name="collision">
                <geometry>
                    <cylinder>
                        <radius>0.1495</radius>
                        <length>0.1</length>
                    </cylinder>
                </geometry>
                <surface>
                    <friction>
                        <ode>
                            <mu>100000.0</mu>
                            <mu2>100000.0</mu2>
                            <slip1>0.0</slip1>
                            <slip2>0.0</slip2>
                        </ode>
                    </friction>
                </surface>
            </collision>
            <visual name="visual">
                <geometry>
                    <mesh>
                        <uri>model://elias/meshes/wheel.dae</uri>
                    </mesh>
                </geometry>
                <material>
                    <script>
                        <uri>file://media/materials/scripts/gazebo.material</uri>
                        <name>Gazebo/Yellow</name>
                    </script>
                </material>
            </visual>
            <velocity_decay>
                <linear>0</linear>
                <angular>0</angular>
            </velocity_decay>
        </link>
        <link name="left_front_connector">
            <pose>0.53 0.205 -0.0466 0 0 0</pose>
            <inertial>
                <mass>0.1</mass>
            </inertial>
            <collision name="vertical">
                <pose>0 0 0.0233 0 0 0</pose>
                <geometry>
                    <cylinder>
                        <radius>0.03</radius>
                        <length>0.0466</length>
                    </cylinder>
                </geometry>
            </collision>
            <collision name="horizontal">
                <pose>0 0.065 0 1.57 0 0</pose>
                <geometry>
                    <cylinder>
                        <radius>0.03</radius>
                        <length>0.13</length>
                    </cylinder>
                </geometry>
            </collision>
            <visual name="vertical">
                <pose>0 0 0.0233 0 0 0</pose>
                <geometry>
                    <cylinder>
                        <radius>0.03</radius>
                        <length>0.0466</length>
                    </cylinder>
                </geometry>
                <material>
                    <script>
                        <uri>file://media/materials/scripts/gazebo.material</uri>
                        <name>Gazebo/White</name>
                    </script>
                </material>
            </visual>
            <visual name="horizontal">
                <pose>0 0.065 0 1.57 0 0</pose>
                <geometry>
                    <cylinder>
                        <radius>0.03</radius>
                        <length>0.13</length>
                    </cylinder>
                </geometry>
                <material>
                    <script>
                        <uri>file://media/materials/scripts/gazebo.material</uri>
                        <name>Gazebo/Green</name>
                    </script>
                </material>
            </visual>
            <velocity_decay>
                <linear>0</linear>
                <angular>0</angular>
            </velocity_decay>
        </link>
        <link name="right_front_connector">
            <pose>0.53 -0.205 -0.0466 0 0 3.14</pose>
            <inertial>
                <mass>0.1</mass>
            </inertial>
            <collision name="vertical">
                <pose>0 0 0.0233 0 0 0</pose>
                <geometry>
                    <cylinder>
                        <radius>0.03</radius>
                        <length>0.0466</length>
                    </cylinder>
                </geometry>
            </collision>
            <collision name="horizontal">
                <pose>0 0.065 0 1.57 0 0</pose>
                <geometry>
                    <cylinder>
                        <radius>0.03</radius>
                        <length>0.13</length>
                    </cylinder>
                </geometry>
            </collision>
            <visual name="vertical">
                <pose>0 0 0.0233 0 0 0</pose>
                <geometry>
                    <cylinder>
                        <radius>0.03</radius>
                        <length>0.0466</length>
                    </cylinder>
                </geometry>
                <material>
                    <script>
                        <uri>file://media/materials/scripts/gazebo.material</uri>
                        <name>Gazebo/White</name>
                    </script>
                </material>
            </visual>
            <visual name="horizontal">
                <pose>0 0.065 0 1.57 0 0</pose>
                <geometry>
                    <cylinder>
                        <radius>0.03</radius>
                        <length>0.13</length>
                    </cylinder>
                </geometry>
                <material>
                    <script>
                        <uri>file://media/materials/scripts/gazebo.material</uri>
                        <name>Gazebo/Green</name>
                    </script>
                </material>
            </visual>
            <velocity_decay>
                <linear>0</linear>
                <angular>0</angular>
            </velocity_decay>
        </link>
        <link name="left_rear_connector">
            <pose>-0.53 0.205 -0.0466 0 0 0</pose>
            <inertial>
                <mass>0.1</mass>
            </inertial>
            <collision name="vertical">
                <pose>0 0 0.0233 0 0 0</pose>
                <geometry>
                    <cylinder>
                        <radius>0.03</radius>
                        <length>0.0466</length>
                    </cylinder>
                </geometry>
            </collision>
            <collision name="horizontal">
                <pose>0 0.065 0 1.57 0 0</pose>
                <geometry>
                    <cylinder>
                        <radius>0.03</radius>
                        <length>0.13</length>
                    </cylinder>
                </geometry>
            </collision>
            <visual name="vertical">
                <pose>0 0 0.0233 0 0 0</pose>
                <geometry>
                    <cylinder>
                        <radius>0.03</radius>
                        <length>0.0466</length>
                    </cylinder>
                </geometry>
                <material>
                    <script>
                        <uri>file://media/materials/scripts/gazebo.material</uri>
                        <name>Gazebo/White</name>
                    </script>
                </material>
            </visual>
            <visual name="horizontal">
                <pose>0 0.065 0 1.57 0 0</pose>
                <geometry>
                    <cylinder>
                        <radius>0.03</radius>
                        <length>0.13</length>
                    </cylinder>
                </geometry>
                <material>
                    <script>
                        <uri>file://media/materials/scripts/gazebo.material</uri>
                        <name>Gazebo/Green</name>
                    </script>
                </material>
            </visual>
            <velocity_decay>
                <linear>0</linear>
                <angular>0</angular>
            </velocity_decay>
        </link>
        <link name="right_rear_connector">
            <pose>-0.53 -0.205 -0.0466 0 0 3.14</pose>
            <inertial>
                <mass>0.1</mass>
            </inertial>
            <collision name="vertical">
                <pose>0 0 0.0233 0 0 0</pose>
                <geometry>
                    <cylinder>
                        <radius>0.03</radius>
                        <length>0.0466</length>
                    </cylinder>
                </geometry>
            </collision>
            <collision name="horizontal">
                <pose>0 0.065 0 1.57 0 0</pose>
                <geometry>
                    <cylinder>
                        <radius>0.03</radius>
                        <length>0.13</length>
                    </cylinder>
                </geometry>
            </collision>
            <visual name="vertical">
                <pose>0 0 0.0233 0 0 0</pose>
                <geometry>
                    <cylinder>
                        <radius>0.03</radius>
                        <length>0.0466</length>
                    </cylinder>
                </geometry>
                <material>
                    <script>
                        <uri>file://media/materials/scripts/gazebo.material</uri>
                        <name>Gazebo/White</name>
                    </script>
                </material>
            </visual>
            <visual name="horizontal">
                <pose>0 0.065 0 1.57 0 0</pose>
                <geometry>
                    <cylinder>
                        <radius>0.03</radius>
                        <length>0.13</length>
                    </cylinder>
                </geometry>
                <material>
                    <script>
                        <uri>file://media/materials/scripts/gazebo.material</uri>
                        <name>Gazebo/Green</name>
                    </script>
                </material>
            </visual>
            <velocity_decay>
                <linear>0</linear>
                <angular>0</angular>
            </velocity_decay>
        </link>
        <joint type="revolute" name="left_front_driving_hinge">
            <pose>0 0 0 0 0 0</pose>
            <axis>
                <xyz>0 1 0</xyz>
            </axis>
            <parent>
                <link_name>left_front_connector</link_name>
            </parent>
            <child>
                <link_name>left_front_wheel</link_name>
            </child>
        </joint>
        <joint type="revolute" name="right_front_driving_hinge">
            <pose>0 0 0 0 0 0</pose>
            <axis>
                <xyz>0 1 0</xyz>
            </axis>
            <parent>
                <link_name>right_front_connector</link_name>
            </parent>
            <child>
                <link_name>right_front_wheel</link_name>
            </child>
        </joint>
        <joint type="revolute" name="left_rear_driving_hinge">
            <pose>0 0 0 0 0 0</pose>
            <axis>
                <xyz>0 1 0</xyz>
            </axis>
            <parent>
                <link_name>left_rear_connector</link_name>
            </parent>
            <child>
                <link_name>left_rear_wheel</link_name>
            </child>
        </joint>
        <joint type="revolute" name="right_rear_driving_hinge">
            <pose>0 0 0 0 0 0</pose>
            <axis>
                <xyz>0 1 0</xyz>
            </axis>
            <parent>
                <link_name>right_rear_connector</link_name>
            </parent>
            <child>
                <link_name>right_rear_wheel</link_name>
            </child>
        </joint>
        <joint type="revolute" name="left_front_steering_hinge">
            <pose>0 0 0.1 0 0 0</pose>
            <axis>
                <xyz>0 0 1</xyz>
                <limit>
                    <lower>-1.57</lower>
                    <upper>1.57</upper>
                </limit>
            </axis>
            <parent>
                <link_name>chassis</link_name>
            </parent>
            <child>
                <link_name>left_front_connector</link_name>
            </child>
        </joint>
        <joint type="revolute" name="right_front_steering_hinge">
            <pose>0 0 0.1 0 0 0</pose>
            <axis>
                <xyz>0 0 1</xyz>
                <limit>
                    <lower>-1.57</lower>
                    <upper>1.57</upper>
                </limit>
            </axis>
            <parent>
                <link_name>chassis</link_name>
            </parent>
            <child>
                <link_name>right_front_connector</link_name>
            </child>
        </joint>
        <joint type="revolute" name="left_rear_steering_hinge">
            <pose>0 0 0.1 0 0 0</pose>
            <axis>
                <xyz>0 0 1</xyz>
                <limit>
                    <lower>-1.57</lower>
                    <upper>1.57</upper>
                </limit>
            </axis>
            <parent>
                <link_name>chassis</link_name>
            </parent>
            <child>
                <link_name>left_rear_connector</link_name>
            </child>
        </joint>
        <joint type="revolute" name="right_rear_steering_hinge">
            <pose>0 0 0.1 0 0 0</pose>
            <axis>
                <xyz>0 0 1</xyz>
                <limit>
                    <lower>-1.57</lower>
                    <upper>1.57</upper>
                </limit>
            </axis>
            <parent>
                <link_name>chassis</link_name>
            </parent>
            <child>
                <link_name>right_rear_connector</link_name>
            </child>
        </joint>
        <include>
            <uri>model://hokuyo</uri>
            <pose>0.56 0 0.085 0 0 0</pose> 
        </include>
        <joint name="hokuyo_joint" type="revolute">
            <child>
                <link_name>hokuyo::link</link_name>
            </child>
            <parent>
                <link_name>chassis</link_name>
            </parent>
            <axis>
                <xyz>0 0 1</xyz>
                <limit>
                    <upper>0</upper>
                    <lower>0</lower>
                </limit>
            </axis>
        </joint>
        <plugin name="all_wheel_steering_plugin" filename="libAllWheelSteeringPlugin.so">
            <left_front_driving_hinge>left_front_driving_hinge</left_front_driving_hinge>
            <right_front_driving_hinge>right_front_driving_hinge</right_front_driving_hinge>
            <left_rear_driving_hinge>left_rear_driving_hinge</left_rear_driving_hinge>
            <right_rear_driving_hinge>right_rear_driving_hinge</right_rear_driving_hinge>
            <left_front_steering_hinge>left_front_steering_hinge</left_front_steering_hinge>
            <right_front_steering_hinge>right_front_steering_hinge</right_front_steering_hinge>
            <left_rear_steering_hinge>left_rear_steering_hinge</left_rear_steering_hinge>
            <right_rear_steering_hinge>right_rear_steering_hinge</right_rear_steering_hinge>
        </plugin>
        <plugin name="odometry_plugin" filename="libLunaboticsOdometryPlugin.so" />
        <plugin name="transform_plugin" filename="libTransformServerPlugin.so" />
    </model>
</sdf>
