<?xml version="1.0" ?>
<sdf version="1.4">
    <model name="elias">
        <pose>0 0 0.1961 0 0 0</pose>
        <static>false</static>
        <link name="chassis">
            <inertial>
                <mass>20.0</mass>
                <inertia>
                    <ixx>1.0</ixx>
                    <ixy>0.0</ixy>
                    <ixz>0.0</ixz>
                    <iyy>1.0</iyy>
                    <iyz>0.0</iyz>
                    <izz>1.0</izz>
                </inertia>
            </inertial>
            <velocity_decay>
				<linear>0.0</linear>
				<angular>0.01</angular>
            </velocity_decay>
            <collision name="main_frame">
                <pose>0.0825 0 0 0 0 0</pose>
                <geometry>
                    <box>
                        <size>1.06 0.16 0.16</size>
                    </box>
                </geometry>
            </collision>
            <collision name="bucket">
				<pose>0.53 0 0.15 1.57 0 3.14</pose>
                <geometry>
                    <mesh>
                        <uri>model://elias/meshes/bucket.dae</uri>
                    </mesh>
                </geometry>
            </collision>
            <collision name="lidar_platform">
                <pose>0.56 0 0.075 0 0 0</pose>
                <geometry>
                    <box>
                        <size>0.05 0.05 0.05</size>
                    </box>
                </geometry>
            </collision>
            <visual name="main_frame">
                <pose>0.0825 0 0 0 0 0</pose>
                <geometry>
                    <box>
                        <size>1.06 0.16 0.16</size>
                    </box>
                </geometry>
                <material>
                    <script>
                        <uri>model://elias/materials/scripts/elias.material</uri>
                        <uri>model://elias/materials/textures/steel.jpg</uri>
                        <name>Lunabotics/Steel</name>
                    </script>
                </material>
            </visual>
          <!--  <visual name="bucket">
				<pose>0.53 0 0.15 1.57 0 3.14</pose>
                <geometry>
                    <mesh>
                        <uri>model://elias/meshes/bucket.dae</uri>
                    </mesh>
                </geometry>
                <material>
                    <script>
                        <uri>file://media/materials/scripts/gazebo.material</uri>
                        <name>Gazebo/White</name>
                    </script>
                </material>
            </visual>-->
            <visual name="lidar_platform">
                <pose>0.56 0 0.075 0 0 0</pose>
                <geometry>
                    <box>
                        <size>0.05 0.05 0.05</size>
                    </box>
                </geometry>
                <material>
                    <script>
                        <uri>model://elias/materials/scripts/elias.material</uri>
                        <uri>model://elias/materials/textures/steel.jpg</uri>
                        <name>Lunabotics/Steel</name>
                    </script>
                </material>
            </visual>
            <velocity_decay>
                <linear>0</linear>
                <angular>0</angular>
            </velocity_decay>
        </link>
        <link name="rear_axle">
			<pose>-0.53 0 0 0 0 0</pose>
            <velocity_decay>
				<linear>0.0</linear>
				<angular>0.01</angular>
            </velocity_decay>
            <collision name="collision">
                <geometry>
                    <box>
                        <size>0.165 0.16 0.16</size>
                    </box>
                </geometry>
            </collision>
            <visual name="visual">
                <geometry>
                    <box>
                        <size>0.165 0.16 0.16</size>
                    </box>
                </geometry>
                <material>
                    <script>
                        <uri>model://elias/materials/scripts/elias.material</uri>
                        <uri>model://elias/materials/textures/steel.jpg</uri>
                        <name>Lunabotics/Steel</name>
                    </script>
                </material>
            </visual>
        </link>
        
        <include>
            <uri>model://sandwich</uri>
			<name>left_front_sandwich</name> 
            <pose>0.53 0.1425 0.02 0 0 0</pose>
        </include>
        
        <include>
            <uri>model://sandwich</uri>
			<name>right_front_sandwich</name> 
            <pose>0.53 -0.1425 0.02 0 0 3.14</pose>
        </include>
        
        <include>
            <uri>model://sandwich</uri>
			<name>left_rear_sandwich</name> 
            <pose>-0.53 0.1425 0.02 0 0 0</pose>
        </include>
        <include>
            <uri>model://sandwich</uri>
			<name>right_rear_sandwich</name> 
            <pose>-0.53 -0.1425 0.02 0 0 3.14</pose>
        </include>
        
        
        
        <include>
            <uri>model://wheel</uri>
			<name>left_front_wheel</name> 
            <pose>0.53 0.335 -0.0466 0 1.57 1.57</pose>
        </include>
        
        <include>
            <uri>model://wheel</uri>
			<name>right_front_wheel</name> 
            <pose>0.53 -0.335 -0.0466 0 1.57 1.57</pose>
        </include>
        
        <include>
            <uri>model://wheel</uri>
			<name>left_rear_wheel</name> 
            <pose>-0.53 0.335 -0.0466 0 1.57 1.57</pose>
        </include>
        
        <include>
            <uri>model://wheel</uri>
			<name>right_rear_wheel</name> 
            <pose>-0.53 -0.335 -0.0466 0 1.57 1.57</pose>
        </include>
        
        
        
        <include>
            <uri>model://connector</uri>
			<name>left_front_connector</name> 
            <pose>0.53 0.205 -0.0466 0 0 0</pose>
        </include>
        
        <include>
            <uri>model://connector</uri>
			<name>right_front_connector</name> 
            <pose>0.53 -0.205 -0.0466 0 0 3.14</pose>
        </include>
        
        <include>
            <uri>model://connector</uri>
			<name>left_rear_connector</name> 
            <pose>-0.53 0.205 -0.0466 0 0 0</pose>
        </include>
        
        <include>
            <uri>model://connector</uri>
			<name>right_rear_connector</name> 
            <pose>-0.53 -0.205 -0.0466 0 0 3.14</pose>
        </include>
        
        
        <include>
            <uri>model://hokuyo</uri>
            <pose>0.56 0 0.135 0 0 0</pose> 
        </include>
        
        <joint type="revolute" name="left_front_driving_hinge">
            <pose>0 0 0 0 0 0</pose>
            <axis>
                <xyz>0 1 0</xyz>
            </axis>
            <physics>
				<ode>
					<max_force>22</max_force>
					<velocity>60</velocity>
				</ode>
            </physics>
            <parent>left_front_connector::holder</parent>
            <child>left_front_wheel::link</child>
        </joint>
        <joint type="revolute" name="right_front_driving_hinge">
            <pose>0 0 0 0 0 0</pose>
            <axis>
                <xyz>0 1 0</xyz>
            </axis>
            <physics>
				<ode>
					<max_force>22</max_force>
					<velocity>60</velocity>
				</ode>
            </physics>
            <parent>right_front_connector::holder</parent>
            <child>right_front_wheel::link</child>
        </joint>
        <joint type="revolute" name="left_rear_driving_hinge">
            <pose>0 0 0 0 0 0</pose>
            <axis>
                <xyz>0 1 0</xyz>
            </axis>
            <physics>
				<ode>
					<max_force>22</max_force>
					<velocity>60</velocity>
				</ode>
            </physics>
            <parent>left_rear_connector::holder</parent>
            <child>left_rear_wheel::link</child>
        </joint>
        <joint type="revolute" name="right_rear_driving_hinge">
            <pose>0 0 0 0 0 0</pose>
            <axis>
                <xyz>0 1 0</xyz>
            </axis>
            <physics>
				<ode>
					<max_force>22</max_force>
					<velocity>60</velocity>
				</ode>
            </physics>
            <parent>right_rear_connector::holder</parent>
            <child>right_rear_wheel::link</child>
        </joint>
        
        <joint type="revolute" name="left_front_steering_hinge">
            <pose>0 0 0.008 0 0 0</pose>
            <axis>
                <xyz>0 0 1</xyz>
                <dynamics>
					<damping>0.0</damping>
					<friction>1000</friction>
                </dynamics>
                <limit>
                    <lower>-1.57</lower>
                    <upper>1.134</upper>
                </limit>
            </axis>
            <physics>
				<ode>
					<cfm>0.0</cfm>
					<bounce>0.01</bounce>
					<max_force>16.5</max_force>
					<velocity>40</velocity>
					<limit>
						<cfm>0.0</cfm>
						<erp>0.0</erp>
					</limit>
				</ode>
            </physics>
            <parent>left_front_sandwich::link</parent>
            <child>left_front_connector::holder</child>
        </joint>
        <joint type="revolute" name="right_front_steering_hinge">
            <pose>0 0 0.008 0 0 0</pose>
            <axis>
                <xyz>0 0 1</xyz>
                <dynamics>
					<damping>0.0</damping>
					<friction>1000</friction>
                </dynamics>
                <limit>
                    <lower>-1.134</lower>
                    <upper>1.57</upper>
                </limit>
            </axis>
            <physics>
				<ode>
					<cfm>0.0</cfm>
					<bounce>0.01</bounce>
					<max_force>16.5</max_force>
					<velocity>40</velocity>
				</ode>
            </physics>
            <parent>right_front_sandwich::link</parent>
            <child>right_front_connector::holder</child>
        </joint>
        <joint type="revolute" name="left_rear_steering_hinge">
            <pose>0 0 0.008 0 0 0</pose>
            <axis>
                <xyz>0 0 1</xyz>
                <dynamics>
					<damping>0.0</damping>
					<friction>1000</friction>
                </dynamics>
                <limit>
                    <lower>-1.134</lower>
                    <upper>1.57</upper>
                </limit>
            </axis>
            <physics>
				<ode>
					<cfm>0.0</cfm>
					<bounce>0.01</bounce>
					<max_force>16.5</max_force>
					<velocity>40</velocity>
				</ode>
            </physics>
            <parent>left_rear_sandwich::link</parent>
            <child>left_rear_connector::holder</child>
        </joint>
        <joint type="revolute" name="right_rear_steering_hinge">
            <pose>0 0 0.008 0 0 0</pose>
            <axis>
                <xyz>0 0 1</xyz>
                <dynamics>
					<damping>0.0</damping>
					<friction>1000</friction>
                </dynamics>
                <limit>
                    <lower>-1.57</lower>
                    <upper>1.134</upper>
                </limit>
            </axis>
            <physics>
				<ode>
					<cfm>0.0</cfm>
					<bounce>0.01</bounce>
					<max_force>16.5</max_force>
					<velocity>40</velocity>
				</ode>
            </physics>
            <parent>right_rear_sandwich::link</parent>
            <child>right_rear_connector::holder</child>
        </joint>
        <joint type="revolute" name="rear_axle_pivot">
            <pose>0.0825 0 0 0 0 0</pose>
            <axis>
                <xyz>1 0 0</xyz>
                <limit>
                    <lower>-0.52</lower>
                    <upper>0.52</upper>
                </limit>
            </axis>
            <parent>chassis</parent>
            <child>rear_axle</child>
        </joint>
        <joint name="hokuyo_joint" type="revolute">
            <child>hokuyo::link</child>
            <parent>chassis</parent>
            <axis>
                <xyz>0 0 1</xyz>
                <limit>
                    <upper>0</upper>
                    <lower>0</lower>
                </limit>
            </axis>
        </joint>
        <joint name="left_front_sandwich" type="revolute">
            <pose>0 -0.0625 0 0 0 0</pose>
            <child>left_front_sandwich::link</child>
            <parent>chassis</parent>
            <axis>
                <xyz>0 1 0</xyz>
                <limit>
                    <upper>0</upper>
                    <lower>0</lower>
                </limit>
            </axis>
        </joint>
        <joint name="right_front_sandwich" type="revolute">
            <pose>0 -0.0625 0 0 0 0</pose>
            <child>right_front_sandwich::link</child>
            <parent>chassis</parent>
            <axis>
                <xyz>0 1 0</xyz>
                <limit>
                    <upper>0</upper>
                    <lower>0</lower>
                </limit>
            </axis>
        </joint>
        <joint name="left_rear_sandwich" type="revolute">
            <pose>0 -0.0625 0 0 0 0</pose>
            <child>left_rear_sandwich::link</child>
            <parent>rear_axle</parent>
            <axis>
                <xyz>0 1 0</xyz>
                <limit>
                    <upper>0</upper>
                    <lower>0</lower>
                </limit>
            </axis>
        </joint>
        <joint name="right_rear_sandwich" type="revolute">
            <pose>0 -0.0625 0 0 0 0</pose>
            <child>right_rear_sandwich::link</child>
            <parent>rear_axle</parent>
            <axis>
                <xyz>0 1 0</xyz>
                <limit>
                    <upper>0</upper>
                    <lower>0</lower>
                </limit>
            </axis>
        </joint>
        <plugin name="all_wheel_steering_plugin" filename="libAllWheelSteeringPlugin.so" />
        <plugin name="odometry_plugin" filename="libLunaboticsOdometryPlugin.so" />
        <plugin name="transform_plugin" filename="libTransformServerPlugin.so" />
    </model>
</sdf>
