<?xml version="1.0" ?>
<sdf version="1.4">
    <model name="elias">
        <pose>0 0 0.61 0 0 0</pose>
        <static>false</static>
        <link name="chassis">
            <inertial>
                <mass>1.0</mass>
                <inertia>
                    <ixx>1.0</ixx>
                    <ixy>0.0</ixy>
                    <ixz>0.0</ixz>
                    <iyy>1.0</iyy>
                    <iyz>0.0</iyz>
                    <izz>1.0</izz>
                </inertia>
            </inertial>
            <collision name="collision">
                <geometry>
                    <box>
                        <size>1 1 1</size>
                    </box>
                </geometry>
            </collision>
            <visual name="base">
                <pose>0 0 -0.4 0 0 0</pose>
                <geometry>
                    <box>
                        <size>0.1 0.9 0.1</size>
                    </box>
                </geometry>
                <material>
                    <script>
                        <uri>file://media/materials/scripts/gazebo.material</uri>
                        <name>Gazebo/Wood</name>
                    </script>
                </material>
            </visual>
            <visual name="front_bar">
                <pose>0 0.5 -0.4 0 0 0</pose>
                <geometry>
                    <box>
                        <size>0.75 0.1 0.1</size>
                    </box>
                </geometry>
                <material>
                    <script>
                        <uri>file://media/materials/scripts/gazebo.material</uri>
                        <name>Gazebo/Wood</name>
                    </script>
                </material>
            </visual>
            <visual name="rear_bar">
                <pose>0 -0.5 -0.4 0 0 0</pose>
                <geometry>
                    <box>
                        <size>0.75 0.1 0.1</size>
                    </box>
                </geometry>
                <material>
                    <script>
                        <uri>file://media/materials/scripts/gazebo.material</uri>
                        <name>Gazebo/Wood</name>
                    </script>
                </material>
            </visual>
            <visual name="monkey">
                <pose>0 0 0.04 0 0 3.14</pose>
                <geometry>
                    <mesh>
                       <uri>model://elias/monkey.dae</uri>
                    </mesh>
                </geometry>
            </visual>
            <visual name="support">
                <pose>0 0 -0.15 0 0 0</pose>
                <geometry>
                    <box>
                        <size>0.1 0.1 0.4</size>
                    </box>
                </geometry>
                <material>
                    <script>
                        <uri>file://media/materials/scripts/gazebo.material</uri>
                        <name>Gazebo/Red</name>
                    </script>
                </material>
            </visual>
        </link>
        <link name="left_front_wheel">
            <pose>0.5 0.5 -0.5 0 1.57 0</pose>
            <inertial>
                <mass>0.1</mass>
            </inertial>
            <collision name="collision">
                <geometry>
                    <cylinder>
                        <radius>0.11</radius>
                        <length>0.05</length>
                    </cylinder>
                </geometry>
                <surface>
                    <friction>
                        <ode>
                            <mu>100000.0</mu>
                            <mu2>100000.0</mu2>
                            <slip1>0.0</slip1>
                            <slip2>0.0</slip2>
                        </ode>
                    </friction>
                </surface>
            </collision>
            <visual name="visual">
                <geometry>
                    <cylinder>
                        <radius>0.11</radius>
                        <length>0.05</length>
                    </cylinder>
                </geometry>
                <material>
                    <script>
                        <uri>file://media/materials/scripts/gazebo.material</uri>
                        <name>Gazebo/FlatBlack</name>
                    </script>
                </material>
            </visual>
        </link>
        <link name="right_front_wheel">
            <pose>-0.5 0.5 -0.5 0 1.57 0</pose>
            <inertial>
                <mass>0.1</mass>
            </inertial>
            <collision name="collision">
                <geometry>
                    <cylinder>
                        <radius>0.11</radius>
                        <length>0.05</length>
                    </cylinder>
                </geometry>
                <surface>
                    <friction>
                        <ode>
                            <mu>100000.0</mu>
                            <mu2>100000.0</mu2>
                            <slip1>0.0</slip1>
                            <slip2>0.0</slip2>
                        </ode>
                    </friction>
                </surface>
            </collision>
            <visual name="visual">
                <geometry>
                    <cylinder>
                        <radius>0.11</radius>
                        <length>0.05</length>
                    </cylinder>
                </geometry>
                <material>
                    <script>
                        <uri>file://media/materials/scripts/gazebo.material</uri>
                        <name>Gazebo/FlatBlack</name>
                    </script>
                </material>
            </visual>
        </link>
        <link name="left_rear_wheel">
            <pose>-0.5 -0.5 -0.5 0 1.57 0</pose>
            <inertial>
                <mass>0.1</mass>
            </inertial>
            <collision name="collision">
                <geometry>
                    <cylinder>
                        <radius>0.11</radius>
                        <length>0.05</length>
                    </cylinder>
                </geometry>
                <surface>
                    <friction>
                        <ode>
                            <mu>100000.0</mu>
                            <mu2>100000.0</mu2>
                            <slip1>0.0</slip1>
                            <slip2>0.0</slip2>
                        </ode>
                    </friction>
                </surface>
            </collision>
            <visual name="visual">
                <geometry>
                    <cylinder>
                        <radius>0.11</radius>
                        <length>0.05</length>
                    </cylinder>
                </geometry>
                <material>
                    <script>
                        <uri>file://media/materials/scripts/gazebo.material</uri>
                        <name>Gazebo/FlatBlack</name>
                    </script>
                </material>
            </visual>
        </link>
        <link name="right_rear_wheel">
            <pose>0.5 -0.5 -0.5 0 1.57 0</pose>
            <inertial>
                <mass>0.1</mass>
            </inertial>
            <collision name="collision">
                <geometry>
                    <cylinder>
                        <radius>0.11</radius>
                        <length>0.05</length>
                    </cylinder>
                </geometry>
                <surface>
                    <friction>
                        <ode>
                            <mu>100000.0</mu>
                            <mu2>100000.0</mu2>
                            <slip1>0.0</slip1>
                            <slip2>0.0</slip2>
                        </ode>
                    </friction>
                </surface>
            </collision>
            <visual name="visual">
                <geometry>
                    <cylinder>
                        <radius>0.11</radius>
                        <length>0.05</length>
                    </cylinder>
                </geometry>
                <material>
                    <script>
                        <uri>file://media/materials/scripts/gazebo.material</uri>
                        <name>Gazebo/FlatBlack</name>
                    </script>
                </material>
            </visual>
        </link>
        <link name="left_front_connector">
            <pose>-0.45 0.5 -0.48 0 0 0</pose>
            <inertial>
                <mass>0.1</mass>
            </inertial>
            <visual name="vertical">
				<pose>0.05 0 0.05 0 0 0</pose>
                <geometry>
                    <cylinder>
                        <radius>0.03</radius>
                        <length>0.10</length>
                    </cylinder>
                </geometry>
                <material>
                    <script>
                        <uri>file://media/materials/scripts/gazebo.material</uri>
                        <name>Gazebo/White</name>
                    </script>
                </material>
            </visual>
            <visual name="horizontal">
				<pose>0 0 0 0 1.57 0</pose>
                <geometry>
                    <cylinder>
                        <radius>0.03</radius>
                        <length>0.10</length>
                    </cylinder>
                </geometry>
                <material>
                    <script>
                        <uri>file://media/materials/scripts/gazebo.material</uri>
                        <name>Gazebo/Green</name>
                    </script>
                </material>
            </visual>
        </link>
        <link name="right_front_connector">
            <pose>0.45 0.5 -0.48 0 0 3.14</pose>
            <inertial>
                <mass>0.1</mass>
            </inertial>
            <visual name="vertical">
				<pose>0.05 0 0.05 0 0 0</pose>
                <geometry>
                    <cylinder>
                        <radius>0.03</radius>
                        <length>0.10</length>
                    </cylinder>
                </geometry>
                <material>
                    <script>
                        <uri>file://media/materials/scripts/gazebo.material</uri>
                        <name>Gazebo/White</name>
                    </script>
                </material>
            </visual>
            <visual name="horizontal">
				<pose>0 0 0 0 1.57 0</pose>
                <geometry>
                    <cylinder>
                        <radius>0.03</radius>
                        <length>0.10</length>
                    </cylinder>
                </geometry>
                <material>
                    <script>
                        <uri>file://media/materials/scripts/gazebo.material</uri>
                        <name>Gazebo/Green</name>
                    </script>
                </material>
            </visual>
        </link>
        <link name="left_rear_connector">
            <pose>-0.45 -0.5 -0.48 0 0 0</pose>
            <inertial>
                <mass>0.1</mass>
            </inertial>
            <visual name="vertical">
				<pose>0.05 0 0.05 0 0 0</pose>
                <geometry>
                    <cylinder>
                        <radius>0.03</radius>
                        <length>0.10</length>
                    </cylinder>
                </geometry>
                <material>
                    <script>
                        <uri>file://media/materials/scripts/gazebo.material</uri>
                        <name>Gazebo/White</name>
                    </script>
                </material>
            </visual>
            <visual name="horizontal">
				<pose>0 0 0 0 1.57 0</pose>
                <geometry>
                    <cylinder>
                        <radius>0.03</radius>
                        <length>0.10</length>
                    </cylinder>
                </geometry>
                <material>
                    <script>
                        <uri>file://media/materials/scripts/gazebo.material</uri>
                        <name>Gazebo/Green</name>
                    </script>
                </material>
            </visual>
        </link>
        <link name="right_rear_connector">
            <pose>0.45 -0.5 -0.48 0 0 3.14</pose>
            <inertial>
                <mass>0.1</mass>
            </inertial>
            <visual name="vertical">
				<pose>0.05 0 0.05 0 0 0</pose>
                <geometry>
                    <cylinder>
                        <radius>0.03</radius>
                        <length>0.10</length>
                    </cylinder>
                </geometry>
                <material>
                    <script>
                        <uri>file://media/materials/scripts/gazebo.material</uri>
                        <name>Gazebo/White</name>
                    </script>
                </material>
            </visual>
            <visual name="horizontal">
				<pose>0 0 0 0 1.57 0</pose>
                <geometry>
                    <cylinder>
                        <radius>0.03</radius>
                        <length>0.10</length>
                    </cylinder>
                </geometry>
                <material>
                    <script>
                        <uri>file://media/materials/scripts/gazebo.material</uri>
                        <name>Gazebo/Green</name>
                    </script>
                </material>
            </visual>
        </link>
        <joint type="revolute" name="left_front_driving_hinge">
            <pose>0 0 0 0 0 0</pose>
            <axis>
                <xyz>0 0 1</xyz>
            </axis>
            <parent>
                <link_name>left_front_connector</link_name>
            </parent>
            <child>
                <link_name>left_front_wheel</link_name>
            </child>
        </joint>
        <joint type="revolute" name="right_front_driving_hinge">
            <pose>0 0 0 0 0 0</pose>
            <axis>
                <xyz>0 0 1</xyz>
            </axis>
            <parent>
                <link_name>right_front_connector</link_name>
            </parent>
            <child>
                <link_name>right_front_wheel</link_name>
            </child>
        </joint>
        <joint type="revolute" name="left_rear_driving_hinge">
            <pose>0 0 0 0 0 0</pose>
            <axis>
                <xyz>0 0 1</xyz>
            </axis>
            <parent>
                <link_name>left_rear_connector</link_name>
            </parent>
            <child>
                <link_name>left_rear_wheel</link_name>
            </child>
        </joint>
        <joint type="revolute" name="right_rear_driving_hinge">
            <pose>0 0 0 0 0 0</pose>
            <axis>
                <xyz>0 0 1</xyz>
            </axis>
            <parent>
                <link_name>right_rear_connector</link_name>
            </parent>
            <child>
                <link_name>right_rear_wheel</link_name>
            </child>
        </joint>
        <joint type="revolute" name="left_front_steering_hinge">
            <pose>0.05 0 0.1 0 0 0</pose>
            <axis>
                <xyz>0 0 1</xyz>
	            <limit>
					<lower>-1.57</lower>
					<upper>1.57</upper>
	            </limit>
            </axis>
            <parent>
                <link_name>chassis</link_name>
            </parent>
            <child>
                <link_name>left_front_connector</link_name>
            </child>
        </joint>
        <joint type="revolute" name="right_front_steering_hinge">
            <pose>0.05 0 0.1 0 0 0</pose>
            <axis>
                <xyz>0 0 1</xyz>
	            <limit>
					<lower>-1.57</lower>
					<upper>1.57</upper>
	            </limit>
            </axis>
            <parent>
                <link_name>chassis</link_name>
            </parent>
            <child>
                <link_name>right_front_connector</link_name>
            </child>
        </joint>
        <joint type="revolute" name="left_rear_steering_hinge">
            <pose>0.05 0 0.1 0 0 0</pose>
            <axis>
                <xyz>0 0 1</xyz>
	            <limit>
					<lower>-1.57</lower>
					<upper>1.57</upper>
	            </limit>
            </axis>
            <parent>
                <link_name>chassis</link_name>
            </parent>
            <child>
                <link_name>left_rear_connector</link_name>
            </child>
        </joint>
        <joint type="revolute" name="right_rear_steering_hinge">
            <pose>0.05 0 0.1 0 0 0</pose>
            <axis>
                <xyz>0 0 1</xyz>
	            <limit>
					<lower>-1.57</lower>
					<upper>1.57</upper>
	            </limit>
            </axis>
            <parent>
                <link_name>chassis</link_name>
            </parent>
            <child>
                <link_name>right_rear_connector</link_name>
            </child>
        </joint>
        <plugin name="ros_model_plugin" filename="libAllWheelSteeringPlugin.so">
			<left_front_driving_hinge>left_front_driving_hinge</left_front_driving_hinge>
			<right_front_driving_hinge>right_front_driving_hinge</right_front_driving_hinge>
			<left_rear_driving_hinge>left_rear_driving_hinge</left_rear_driving_hinge>
			<right_rear_driving_hinge>right_rear_driving_hinge</right_rear_driving_hinge>
			<left_front_steering_hinge>left_front_steering_hinge</left_front_steering_hinge>
			<right_front_steering_hinge>right_front_steering_hinge</right_front_steering_hinge>
			<left_rear_steering_hinge>left_rear_steering_hinge</left_rear_steering_hinge>
			<right_rear_steering_hinge>right_rear_steering_hinge</right_rear_steering_hinge>
        </plugin>
    </model>
</sdf>
